Windows PowerShell
(C) Корпорация Майкрософт (Microsoft Corporation). Все права защищены.

Установите последнюю версию PowerShell для новых функций и улучшения! https://aka.ms/PSWindows

(venv) PS C:\Users\user\PycharmProjects\NewsPortal> cd NewsPaper
(venv) PS C:\Users\user\PycharmProjects\NewsPortal\NewsPaper> python manage.py shell
Python 3.8.10 (tags/v3.8.10:3d8993a, May  3 2021, 11:48:03) [MSC v.1928 64 bit (AMD64)] on win32
Type "help", "copyright", "credits" or "license" for more information.
(InteractiveConsole)
>>> from news.models import *
>>> u1 = User.objects.create_user('Peter')
Traceback (most recent call last):
  File "C:\Users\user\PycharmProjects\NewsPortal\venv\lib\site-packages\django\db\backends\utils.py", line 89, in _execute
    return self.cursor.execute(sql, params)
  File "C:\Users\user\PycharmProjects\NewsPortal\venv\lib\site-packages\django\db\backends\sqlite3\base.py", line 328, in execute
    return super().execute(query, params)
sqlite3.OperationalError: no such table: auth_user

The above exception was the direct cause of the following exception:

Traceback (most recent call last):
  File "<console>", line 1, in <module>
  File "C:\Users\user\PycharmProjects\NewsPortal\venv\lib\site-packages\django\contrib\auth\models.py", line 161, in create_user
    return self._create_user(username, email, password, **extra_fields)
  File "C:\Users\user\PycharmProjects\NewsPortal\venv\lib\site-packages\django\contrib\auth\models.py", line 155, in _create_user
    user.save(using=self._db)
  File "C:\Users\user\PycharmProjects\NewsPortal\venv\lib\site-packages\django\contrib\auth\base_user.py", line 76, in save
    super().save(*args, **kwargs)
  File "C:\Users\user\PycharmProjects\NewsPortal\venv\lib\site-packages\django\db\models\base.py", line 814, in save
    self.save_base(
  File "C:\Users\user\PycharmProjects\NewsPortal\venv\lib\site-packages\django\db\models\base.py", line 877, in save_base
    updated = self._save_table(
  File "C:\Users\user\PycharmProjects\NewsPortal\venv\lib\site-packages\django\db\models\base.py", line 1020, in _save_table
    results = self._do_insert(
  File "C:\Users\user\PycharmProjects\NewsPortal\venv\lib\site-packages\django\db\models\base.py", line 1061, in _do_insert
    return manager._insert(
  File "C:\Users\user\PycharmProjects\NewsPortal\venv\lib\site-packages\django\db\models\manager.py", line 87, in manager_method
    return getattr(self.get_queryset(), name)(*args, **kwargs)
  File "C:\Users\user\PycharmProjects\NewsPortal\venv\lib\site-packages\django\db\models\query.py", line 1805, in _insert
    return query.get_compiler(using=using).execute_sql(returning_fields)
  File "C:\Users\user\PycharmProjects\NewsPortal\venv\lib\site-packages\django\db\models\sql\compiler.py", line 1822, in execute_sql
    cursor.execute(sql, params)
  File "C:\Users\user\PycharmProjects\NewsPortal\venv\lib\site-packages\django\db\backends\utils.py", line 102, in execute
    return super().execute(sql, params)
  File "C:\Users\user\PycharmProjects\NewsPortal\venv\lib\site-packages\django\db\backends\utils.py", line 67, in execute
    return self._execute_with_wrappers(
  File "C:\Users\user\PycharmProjects\NewsPortal\venv\lib\site-packages\django\db\backends\utils.py", line 80, in _execute_with_wrappers
    return executor(sql, params, many, context)
  File "C:\Users\user\PycharmProjects\NewsPortal\venv\lib\site-packages\django\db\backends\utils.py", line 89, in _execute
    return self.cursor.execute(sql, params)
  File "C:\Users\user\PycharmProjects\NewsPortal\venv\lib\site-packages\django\db\utils.py", line 91, in __exit__
    raise dj_exc_value.with_traceback(traceback) from exc_value
  File "C:\Users\user\PycharmProjects\NewsPortal\venv\lib\site-packages\django\db\backends\utils.py", line 89, in _execute
    return self.cursor.execute(sql, params)
  File "C:\Users\user\PycharmProjects\NewsPortal\venv\lib\site-packages\django\db\backends\sqlite3\base.py", line 328, in execute
    return super().execute(query, params)
django.db.utils.OperationalError: no such table: auth_user
